Workbook

Sheet Summary
A1: Month | B1: Statement Period | C1: Account No | D1: Beginning Balance ($) | E1: Addition ($) | F1: Subtraction ($) | G1: Trade Transaction ($) | H1: Cost and Fees ($) | I1: Ending Cash ($) | J1: Long ($) | K1: Total Market Value ($) | L1: Dividend ($) | M1: Interest ($) | N1: Realized ST Net ($) | O1: Realized LT Net ($)
A2: 2023-01 | B2: January 2023 | C2: 947159514 | E2: 34.05 | G2: -30.01 | H2: -0.02 | I2: 4.02 | J2: 32.59 | K2: 36.61
A3: 2023-02 | B3: February 2023 | C3: 947159514 | D3: 4.02 | E3: 53.72 | G3: -57.68 | H3: -0.05 | I3: 0.01 | J3: 81.09 | K3: 81.1
A4: 2023-03 | B4: March 2023 | C4: 947159514 | D4: 0.01 | I4: 0.01 | J4: 85.28 | K4: 85.29
A5: 2023-04 | B5: April 2023 | C5: 947159514 | D5: 0.01 | I5: 0.01 | J5: 82.54 | K5: 82.55
A6: 2023-05 | B6: May 2023 | C6: 947159514 | D6: 0.01 | I6: 0.01 | J6: 78.23 | K6: 78.24
A7: 2023-06 | B7: June 2023 | C7: 947159514 | D7: 0.01 | E7: 0.47 | F7: 0.06 | I7: 0.42 | J7: 81.73 | K7: 82.15 | L7: 0.47
A8: 2023-07 | B8: July 2023 | C8: 947159514 | D8: 0.42 | E8: 0.06 | I8: 0.48 | J8: 91 | K8: 91.48 | L8: 0.06
A9: 2023-08 | B9: August 2023 | C9: 947159514 | D9: 0.48 | I9: 0.48 | J9: 85.73 | K9: 86.21
A10: 2023-09 | B10: September 2023 | C10: 947159514 | D10: 0.48 | I10: 0.48 | J10: 80.44 | K10: 80.92
A11: 2023-10 | B11: October 2023 | C11: 947159514 | D11: 0.48 | I11: 0.48 | J11: 73.92 | K11: 74.4
A12: 2023-11 | B12: November 2023 | C12: 947159514 | D12: 0.48 | I12: 0.48 | J12: 78.49 | K12: 78.97
A13: 2023-12 | B13: December 2023 | C13: 947159514 | D13: 0.48 | E13: 120.56 | F13: 0.16 | G13: -119.37 | H13: -0.11 | I13: 1.4 | J13: 202.83 | K13: 204.23 | L13: 1.08
A14: 2024-01 | B14: January 2024 | C14: 947159514 | D14: 1.4 | E14: 40.1 | F14: 0.01 | G14: -33.52 | I14: 7.97 | J14: 225 | K14: 232.97 | L14: 0.1
A15: 2024-02 | B15: February 2024 | C15: 947159514 | D15: 7.97 | E15: 141.2 | G15: -141.2 | I15: 7.97 | J15: 407.56 | K15: 415.53
A16: 2024-03 | B16: March 2024 | C16: 947159514 | D16: 7.97 | E16: 309.73 | F16: 0.17 | G16: -308.11 | H16: -0.41 | I16: 9.01 | J16: 718.85 | K16: 727.86 | L16: 1.21
A17: 2024-04 | B17: April 2024 | C17: 947159514 | D17: 9.01 | E17: 3099.67 | F17: 2.52 | G17: -3081.8 | H17: -0.34 | I17: 24.02 | J17: 3767.26 | K17: 3791.28 | L17: 16.92
A18: 2024-05 | B18: May 2024 | C18: 947159514 | D18: 24.02 | E18: 4183.54 | F18: 486.15 | G18: -3677.87 | H18: -2.46 | I18: 41.08 | J18: 7463.61 | K18: 7504.69 | L18: 34.54
A19: 2024-06 | B19: June 2024 | C19: 947159514 | D19: 41.08 | E19: 2241.45 | F19: 8.65 | G19: -2230.18 | H19: -1.44 | I19: 42.26 | J19: 9674.47 | K19: 9716.73 | L19: 57.95
A20: 2024-07 | B20: July 2024 | C20: 947159514 | D20: 42.26 | E20: 11392.26 | F20: 17.96 | G20: -4012.4 | H20: -5.05 | I20: 7399.11 | J20: 13605.71 | K20: 21004.82 | L20: 120.15
A21: 2024-08 | B21: August 2024 | C21: 947159514 | D21: 7399.11 | E21: 128.74 | F21: 18.17 | G21: -6205.5 | H21: -5.28 | I21: 1298.9 | J21: 19769.4 | K21: 21068.3 | L21: 122.08
A22: 2024-09 | B22: September 2024 | C22: 947159514 | D22: 1298.9 | E22: 1719.26 | F22: 26.97 | G22: -182 | I22: 2809.19 | J22: 19945.55 | K22: 22754.74 | L22: 180.33
A23: 2024-10 | B23: October 2024 | C23: 947159514 | D23: 2809.19 | E23: 320.05 | F23: 47.91 | G23: -2474.84 | H23: -3.06 | I23: 603.43 | J23: 22294.98 | K23: 22898.41 | L23: 320.05
A24: 2024-11 | B24: November 2024 | C24: 947159514 | D24: 603.43 | E24: 3583.02 | F24: 57.1 | G24: -1713.06 | H24: -2.06 | I24: 2414.23 | J24: 24246.06 | K24: 26660.29 | L24: 381.16
A25: 2024-12 | B25: December 2024 | C25: 947159514 | D25: 2414.23 | E25: 2672.16 | F25: 272.21 | G25: -4774.95 | H25: -6.34 | I25: 32.89 | J25: 28334.96 | K25: 28367.85 | L25: 320.05 | M25: 89.42
A26: 2025-01 | B26: January 2025 | C26: 947159514 | D26: 32.89 | E26: 1975.01 | F26: 49.16 | G26: -1789.46 | H26: -2.89 | I26: 166.39 | J26: 30350.5 | K26: 30516.89 | L26: 328.66
A27: 2025-02 | B27: February 2025 | C27: 947159514 | D27: 166.39 | E27: 3019.94 | F27: 56.61 | G27: -2959.01 | H27: -4.81 | I27: 165.9 | J27: 32447.95 | K27: 32613.85 | L27: 378.26 | N27: 1.26
A28: 2025-03 | B28: March 2025 | C28: 947159514 | D28: 165.9 | E28: 1153.59 | F28: 49.06 | G28: -1047.26 | H28: -1.27 | I28: 221.9 | J28: 32636.19 | K28: 32858.09 | L28: 327.98
A29: 2025-04 | B29: April 2025 | C29: 947159514 | D29: 221.9 | E29: 1350.35 | F29: 45.77 | G29: -968.83 | H29: -4.23 | I29: 553.42 | J29: 33470.83 | K29: 34024.25 | L29: 307.57 | N29: -374.77 | O29: -5.21
A30: 2025-05 | B30: May 2025 | C30: 947159514 | D30: 553.42 | E30: 910.01 | F30: 81.51 | G30: -1234.65 | H30: -3.4 | I30: 143.87 | J30: 34854.36 | K30: 34998.23 | L30: 544.35 | N30: -115.81
A31: 2025-06 | B31: June 2025 | C31: 947159514 | D31: 143.87 | E31: 1189.8 | F31: 55.51 | G31: -1235.88 | H31: -4.86 | I31: 37.42 | J31: 36557.37 | K31: 36594.79 | L31: 371.09 | N31: -16.62 | O31: 1.96
A32: 2025-07 | B32: July 2025 | C32: 947159514 | D32: 37.42 | E32: 1077.65 | F32: 59.21 | G32: -645.4 | H32: -13.45 | I32: 397.01 | J32: 37319 | K32: 37716.01 | L32: 396.17 | N32: -220.87
A33: 2025-08 | B33: August 2025 | C33: 947159514 | D33: 397.01 | E33: 456.87 | F33: 68.35 | G33: -74.46 | H33: -10.17 | I33: 700.9 | J33: 36996.78 | K33: 37697.68 | L33: 456.83 | N33: -23.36
A34: 2025-09 | B34: September 2025 | C34: 947159514 | D34: 700.9 | E34: 376.59 | F34: 56.31 | G34: -395.06 | H34: -0.13 | I34: 625.99 | J34: 37384.71 | K34: 38010.7 | L34: 376.59
A35: 2025-10 | B35: October 2025 | C35: 947159514 | D35: 625.99 | E35: 981.72 | F35: 76.39 | G35: -1407.24 | H35: -2.23 | I35: 121.85 | J35: 38731.5 | K35: 38853.35 | L35: 511.26 | N35: 1.03 | O35: 0.83
A36: 2025-11 | B36: November 2025 | C36: 947159514 | D36: 121.85 | E36: 1522.31 | F36: 53.39 | G36: -1569.11 | H36: -2.23 | I36: 19.43 | J36: 39259.76 | K36: 39279.19 | L36: 357.43
A37: 2025-12 | B37: December 2025 | C37: 947159514 | D37: 19.43 | E37: 2213.6 | F37: 77.68 | G37: -2021.57 | H37: -2.36 | I37: 131.42 | J37: 40924.62 | K37: 41056.04 | L37: 520.13 | N37: 237.74 | O37: -237.74
A38: 2026-01 | B38: January 2026 | C38: 947159514 | D38: 131.42 | E38: 2236.01 | F38: 69.84 | G38: -1999.65 | H38: -2.91 | I38: 295.03 | J38: 42691.28 | K38: 42986.31 | L38: 262.41 | N38: 15.49
A39: 2026-02 | B39: February 2026 | C39: 947159514 | D39: 295.03 | E39: 1755.15 | F39: 47.42 | G39: -1836.45 | H39: -1.92 | I39: 164.39 | J39: 43346.18 | K39: 43510.57 | L39: 317.73
A40: 2026-03 | B40: March 2026 | C40: 947159514 | D40: 164.39 | E40: 445.52 | F40: 44.08 | G40: -424.69 | H40: -4.12 | I40: 137.02 | J40: 42963.77 | K40: 43100.79 | L40: 295.52 | N40: -653.04 | O40: -436.94
...

Sheet Holdings
A1: Month | B1: Symbol | C1: Description | D1: Quantity | E1: Market Price | F1: Market Value | G1: Cost Price | H1: Unrealized | I1: TD Cost Basis
A2: 2023-01 | B2: *Cash | C2: USD | D2: $-- | F2: 4.02
A3: 2023-01 | B3: MCHI | C3: ISHARES TR MSCI CHINA ETF | D3: 0.29756297 | E3: 53.58 | F3: 15.94 | G3: 48.83 | H3: 1.41 | I3: 14.53
A4: 2023-01 | B4: VNAM | C4: GLOBAL X FDS MSCI VIETNAM ETF | D4: 1 | E4: 16.65 | F4: 16.65 | G4: 15.48 | H4: 1.17 | I4: 15.48
A5: 2023-02 | B5: *Cash | C5: USD | D5: $-- | F5: 0.01
A6: 2023-02 | B6: MCHI | C6: ISHARES TR MSCI CHINA ETF | D6: 1.0845778 | E6: 47.86 | F6: 51.91 | G6: 51.76 | H6: -4.23 | I6: 56.14
A7: 2023-02 | B7: VNAM | C7: GLOBAL X FDS MSCI VIETNAM ETF | D7: 2 | E7: 14.59 | F7: 29.18 | G7: 15.77 | H7: -2.37 | I7: 31.55
A8: 2023-03 | B8: *Cash | C8: USD | D8: $-- | F8: 0.01
A9: 2023-03 | B9: MCHI | C9: ISHARES TR MSCI CHINA ETF | D9: 1.0845778 | E9: 49.89 | F9: 54.11 | G9: 51.76 | H9: -2.03 | I9: 56.14
A10: 2023-03 | B10: VNAM | C10: GLOBAL X FDS MSCI VIETNAM ETF | D10: 2 | E10: 15.59 | F10: 31.17 | G10: 15.77 | H10: -0.38 | I10: 31.55
A11: 2023-04 | B11: *Cash | C11: USD | D11: $-- | F11: 0.01
A12: 2023-04 | B12: MCHI | C12: ISHARES TR MSCI CHINA ETF | D12: 1.0845778 | E12: 47.72 | F12: 51.76 | G12: 51.76 | H12: -4.38 | I12: 56.14
A13: 2023-04 | B13: VNAM | C13: GLOBAL X FDS MSCI VIETNAM ETF | D13: 2 | E13: 15.39 | F13: 30.78 | G13: 15.77 | H13: -0.77 | I13: 31.55
A14: 2023-05 | B14: *Cash | C14: USD | D14: $-- | F14: 0.01
A15: 2023-05 | B15: MCHI | C15: ISHARES TR MSCI CHINA ETF | D15: 1.0845778 | E15: 43.24 | F15: 46.9 | G15: 51.76 | H15: -9.24 | I15: 56.14
A16: 2023-05 | B16: VNAM | C16: GLOBAL X FDS MSCI VIETNAM ETF | D16: 2 | E16: 15.66 | F16: 31.33 | G16: 15.77 | H16: -0.22 | I16: 31.55
A17: 2023-06 | B17: *Cash | C17: USD | D17: $-- | F17: 0.42
A18: 2023-06 | B18: MCHI | C18: ISHARES TR MSCI CHINA ETF | D18: 1.0845778 | E18: 44.74 | F18: 48.52 | G18: 51.76 | H18: -7.61 | I18: 56.14
A19: 2023-06 | B19: VNAM | C19: GLOBAL X FDS MSCI VIETNAM ETF | D19: 2 | E19: 16.61 | F19: 33.21 | G19: 15.77 | H19: 1.66 | I19: 31.55
A20: 2023-07 | B20: *Cash | C20: USD | D20: $-- | F20: 0.48
A21: 2023-07 | B21: MCHI | C21: ISHARES TR MSCI CHINA ETF | D21: 1.0845778 | E21: 49.8 | F21: 54.01 | G21: 51.76 | H21: -2.13 | I21: 56.14
A22: 2023-07 | B22: VNAM | C22: GLOBAL X FDS MSCI VIETNAM ETF | D22: 2 | E22: 18.49 | F22: 36.98 | G22: 15.77 | H22: 5.43 | I22: 31.55
A23: 2023-08 | B23: *Cash | C23: USD | D23: $-- | F23: 0.48
A24: 2023-08 | B24: MCHI | C24: ISHARES TR MSCI CHINA ETF | D24: 1.0845778 | E24: 44.91 | F24: 48.71 | G24: 51.76 | H24: -7.43 | I24: 56.14
A25: 2023-08 | B25: VNAM | C25: GLOBAL X FDS MSCI VIETNAM ETF | D25: 2 | E25: 18.51 | F25: 37.03 | G25: 15.77 | H25: 5.48 | I25: 31.55
A26: 2023-09 | B26: *Cash | C26: USD | D26: $-- | F26: 0.48
A27: 2023-09 | B27: MCHI | C27: ISHARES TR MSCI CHINA ETF | D27: 1.0845778 | E27: 43.29 | F27: 46.95 | G27: 51.76 | H27: -9.19 | I27: 56.14
A28: 2023-09 | B28: VNAM | C28: GLOBAL X FDS MSCI VIETNAM ETF | D28: 2 | E28: 16.75 | F28: 33.49 | G28: 15.77 | H28: 1.94 | I28: 31.55
A29: 2023-10 | B29: *Cash | C29: USD | D29: $-- | F29: 0.48
A30: 2023-10 | B30: MCHI | C30: ISHARES TR MSCI CHINA ETF | D30: 1.0845778 | E30: 41.81 | F30: 45.35 | G30: 51.76 | H30: -10.79 | I30: 56.14
A31: 2023-10 | B31: VNAM | C31: GLOBAL X FDS MSCI VIETNAM ETF | D31: 2 | E31: 14.29 | F31: 28.58 | G31: 15.77 | H31: -2.97 | I31: 31.55
A32: 2023-11 | B32: *Cash | C32: USD | D32: $-- | F32: 0.48
A33: 2023-11 | B33: MCHI | C33: ISHARES TR MSCI CHINA ETF | D33: 1.0845778 | E33: 42.68 | F33: 46.29 | G33: 51.76 | H33: -9.85 | I33: 56.14
A34: 2023-11 | B34: VNAM | C34: GLOBAL X FDS MSCI VIETNAM ETF | D34: 2 | E34: 16.1 | F34: 32.2 | G34: 15.77 | H34: 0.65 | I34: 31.55
A35: 2023-12 | B35: *Cash | C35: USD | D35: $-- | F35: 1.4
A36: 2023-12 | B36: ARM | C36: ARM HOLDINGS PLC SPONSORED ADR | D36: 0.48281391 | E36: 75.15 | F36: 36.28 | G36: 71.1 | H36: 1.95 | I36: 34.33
A37: 2023-12 | B37: MCHI | C37: ISHARES TR MSCI CHINA ETF | D37: 1.802739 | E37: 40.74 | F37: 73.44 | G37: 47.29 | H37: -11.81 | I37: 85.26
A38: 2023-12 | B38: NDAQ | C38: NASDAQ INC COM | D38: 1.0311636 | E38: 58.14 | F38: 59.95 | G38: 54.23 | H38: 4.03 | I38: 55.92
A39: 2023-12 | B39: VNAM | C39: GLOBAL X FDS MSCI VIETNAM ETF | D39: 2 | E39: 16.58 | F39: 33.16 | G39: 15.77 | H39: 1.61 | I39: 31.55
A40: 2024-01 | B40: *Cash | C40: USD | D40: $-- | F40: 7.97
...

Sheet Transactions
A1: Month | B1: Trade Date | C1: Entry Type | D1: Side | E1: Symbol | F1: Description | G1: Quantity | H1: Price | I1: Amount | J1: Commission
A2: 2023-01 | B2: 01/03/2023 | C2: Trade Entry | D2: buy | E2: MCHI | G2: 0.29756297 | H2: 48.83 | I2: -14.53
A3: 2023-01 | B3: 01/03/2023 | C3: Trade Entry | D3: buy | E3: VNAM | G3: 1 | H3: 15.48 | I3: -15.48 | J3: 0.02
A4: 2023-02 | B4: 02/03/2023 | C4: Trade Entry | D4: buy | E4: MCHI | G4: 0.42331845 | H4: 52.87 | I4: -22.38
A5: 2023-02 | B5: 02/03/2023 | C5: Trade Entry | D5: buy | E5: VNAM | G5: 1 | H5: 16.07 | I5: -16.07 | J5: 0.02
A6: 2023-02 | B6: 02/03/2023 | C6: Trade Entry | D6: buy | E6: MCHI | G6: 0.36369638 | H6: 52.87 | I6: -19.23 | J6: 0.03
A7: 2023-12 | B7: 12/13/2023 | C7: Trade Entry | D7: buy | E7: NDAQ | G7: 1.0311636 | H7: 54.23 | I7: -55.92
A8: 2023-12 | B8: 12/21/2023 | C8: Trade Entry | D8: buy | E8: ARM | G8: 0.48281391 | H8: 71.1 | I8: -34.33 | J8: 0.06
A9: 2023-12 | B9: 12/28/2023 | C9: Trade Entry | D9: buy | E9: MCHI | G9: 0.71816119 | H9: 40.55 | I9: -29.12 | J9: 0.05
A10: 2024-01 | B10: 01/08/2024 | C10: Trade Entry | D10: buy | E10: VNAM | G10: 2 | H10: 16.76 | I10: -33.52
A11: 2024-02 | B11: 02/01/2024 | C11: Trade Entry | D11: buy | E11: SHV | G11: 1.2816789 | H11: 110.17 | I11: -141.2
A12: 2024-03 | B12: 03/07/2024 | C12: Trade Entry | D12: buy | E12: SHV | G12: 0.50908365 | H12: 110.2 | I12: -56.1
A13: 2024-03 | B13: 03/08/2024 | C13: Trade Entry | D13: buy | E13: SHV | G13: 1.2756287 | H13: 110.23 | I13: -140.61 | J13: 0.23
A14: 2024-03 | B14: 03/12/2024 | C14: Trade Entry | D14: buy | E14: QYLD | G14: 1 | H14: 17.98 | I14: -17.98
A15: 2024-03 | B15: 03/12/2024 | C15: Trade Entry | D15: buy | E15: QYLD | G15: 1.3240612 | H15: 17.98 | I15: -23.8 | J15: 0.07
A16: 2024-03 | B16: 03/12/2024 | C16: Trade Entry | D16: buy | E16: SGOV | G16: 0.69302594 | H16: 100.46 | I16: -69.62 | J16: 0.11
A17: 2024-04 | B17: 04/01/2024 | C17: Trade Entry | D17: buy | E17: QYLD | G17: 14 | H17: 17.94 | I17: -251.09
A18: 2024-04 | B18: 04/01/2024 | C18: Trade Entry | D18: buy | E18: QYLD | G18: 1.2171731 | H18: 17.94 | I18: -21.83
A19: 2024-04 | B19: 04/01/2024 | C19: Trade Entry | D19: buy | E19: SHV | G19: 16 | H19: 110.06 | I19: -1760.96
A20: 2024-04 | B20: 04/01/2024 | C20: Trade Entry | D20: buy | E20: SHV | G20: 1.3537162 | H20: 110.06 | I20: -148.99
A21: 2024-04 | B21: 04/01/2024 | C21: Trade Entry | D21: buy | E21: THW | G21: 36 | H21: 13.06 | I21: -470.02
A22: 2024-04 | B22: 04/18/2024 | C22: Trade Entry | D22: buy | E22: KLIP | G22: 15 | H22: 14.55 | I22: -218.25
A23: 2024-04 | B23: 04/29/2024 | C23: Trade Entry | D23: buy | E23: RYLD | G23: 11 | H23: 16.43 | I23: -180.68
A24: 2024-04 | B24: 04/29/2024 | C24: Trade Entry | D24: buy | E24: RYLD | G24: 1.8252664 | H24: 16.43 | I24: -29.98 | J24: 0.34
A25: 2024-05 | B25: 05/01/2024 | C25: Trade Entry | D25: buy | E25: FLTR | G25: 37 | H25: 25.37 | I25: -938.51
A26: 2024-05 | B26: 05/01/2024 | C26: Trade Entry | D26: buy | E26: FLTR | G26: 1.1409422 | H26: 25.37 | I26: -28.94 | J26: 1.55
A27: 2024-05 | B27: 05/01/2024 | C27: Trade Entry | D27: buy | E27: KLIP | G27: 15 | H27: 14.52 | I27: -217.73 | J27: 0.35
A28: 2024-05 | B28: 05/01/2024 | C28: Trade Entry | D28: buy | E28: SGOV | G28: 10 | H28: 100.3 | I28: -1003
A29: 2024-05 | B29: 05/01/2024 | C29: Trade Entry | D29: buy | E29: SGOV | G29: 1.2761715 | H29: 100.3 | I29: -128
A30: 2024-05 | B30: 05/01/2024 | C30: Trade Entry | D30: buy | E30: SHV | G30: 8 | H30: 110.03 | I30: -880.24
A31: 2024-05 | B31: 05/01/2024 | C31: Trade Entry | D31: buy | E31: SHV | G31: 1.1702284 | H31: 110.03 | I31: -128.76
A32: 2024-05 | B32: 05/01/2024 | C32: Trade Entry | D32: buy | E32: THW | G32: 3 | H32: 12.78 | I32: -38.34 | J32: 0.06
A33: 2024-05 | B33: 05/02/2024 | C33: Trade Entry | D33: buy | E33: PFRL | G33: 4 | H33: 50.41 | I33: -201.63 | J33: 0.32
A34: 2024-05 | B34: 05/30/2024 | C34: Trade Entry | D34: buy | E34: KLIP | G34: 8 | H34: 14.09 | I34: -112.72 | J34: 0.18
A35: 2024-06 | B35: 06/03/2024 | C35: Trade Entry | D35: buy | E35: FLTR | G35: 7 | H35: 25.4 | I35: -177.8
A36: 2024-06 | B36: 06/03/2024 | C36: Trade Entry | D36: buy | E36: FLTR | G36: 1.5827021 | H36: 25.4 | I36: -40.2
A37: 2024-06 | B37: 06/03/2024 | C37: Trade Entry | D37: buy | E37: GOOY | G37: 6 | H37: 18.14 | I37: -108.84 | J37: 0.17
A38: 2024-06 | B38: 06/03/2024 | C38: Trade Entry | D38: buy | E38: KLIP | G38: 8 | H38: 13.93 | I38: -111.44 | J38: 0.18
A39: 2024-06 | B39: 06/03/2024 | C39: Trade Entry | D39: buy | E39: PFRL | G39: 2 | H39: 50.46 | I39: -100.92 | J39: 0.16
A40: 2024-06 | B40: 06/03/2024 | C40: Trade Entry | D40: buy | E40: RYLD | G40: 1.3507196 | H40: 16.26 | I40: -21.96 | J40: 0.04
...

Sheet Income
A1: Month | B1: Trade Date | C1: Entry Type | D1: Symbol | E1: Description | F1: Net Amt
A2: 2023-01 | B2: 01/03/2023 | C2: Journal Entry(Cash) | E2: ID: b4729546-67b3-483d-8c77-152913c7a89a - STKSWI20230103054511111950 | F2: 14.53
A3: 2023-01 | B3: 01/03/2023 | C3: Journal Entry(Cash) | E3: ID: e2816bfb-b30f-4f60-81e2-62052d38dfc8 - STKSWI20230103025053112708 | F3: 14.52
A4: 2023-01 | B4: 01/03/2023 | C4: Journal Entry(Cash) | E4: ID: 8afec0a1-64d2-4776-b0bb-06882c1a57fd - STKSWI20230103025331112736 | F4: 5
A5: 2023-02 | B5: 02/03/2023 | C5: Journal Entry(Cash) | E5: ID: b45e44a3-b88d-4ef0-84c6-eae79ad816d0 - STKSWI20230203052647162913 | F5: 22.38
A6: 2023-02 | B6: 02/03/2023 | C6: Journal Entry(Cash) | E6: ID: cb2f3f40-0d7d-4fc6-bf07-a123bb06ef44 - STKSWI20230203052813162918 | F6: 13.43
A7: 2023-02 | B7: 02/03/2023 | C7: Journal Entry(Cash) | E7: ID: b63c5274-577d-4864-ba79-59552edf0cf0 - STKSWI20230203053002162922 | F7: 5.97
A8: 2023-02 | B8: 02/03/2023 | C8: Journal Entry(Cash) | E8: ID: 3857e917-92dd-48f5-a477-8358503b48e0 - STKSWI20230203053121162925 | F8: 11.94
A9: 2023-06 | B9: 06/13/2023 | C9: Dividends | D9: MCHI | E9: Cash DIV @ 0.091277, Pos QTY: 1.084577801, Rec Date: 2023-06-08 | F9: 0.1
A10: 2023-06 | B10: 06/13/2023 | C10: Div. Adj(NRA Withheld) | D10: MCHI | E10: DIV tax withholding on $0.37 at 15% for tax country THA; w8w9: w8 | F10: -0.05
A11: 2023-06 | B11: 06/13/2023 | C11: Dividends | D11: MCHI | E11: Cash DIV @ 0.337912, Pos QTY: 1.084577801, Rec Date: 2023-06-08 | F11: 0.37
A12: 2023-06 | B12: 06/13/2023 | C12: Div. Adj(NRA Withheld) | D12: MCHI | E12: DIV tax withholding on $0.1 at 15% for tax country THA; w8w9: w8 | F12: -0.01
A13: 2023-07 | B13: 07/10/2023 | C13: Dividends | D13: VNAM | E13: Cash DIV @ 0.029971, Pos QTY: 2, Rec Date: 2023-06-30 | F13: 0.06
A14: 2023-12 | B14: 12/12/2023 | C14: Journal Entry(Cash) | E14: ID: 5eb026bc-02b2-420a-8163-637c02d4ab07 - STKSWI20231213031023999052 | F14: 55.92
A15: 2023-12 | B15: 12/21/2023 | C15: Journal Entry(Cash) | E15: ID: 19137a2a-257e-40c7-863f-99bed01e969b - STKSWI20231221043059031020 | F15: 34.39
A16: 2023-12 | B16: 12/27/2023 | C16: Dividends | D16: MCHI | E16: Cash DIV @ 0.994126, Pos QTY: 1.084577801, Rec Date: 2023-12-21 | F16: 1.08
A17: 2023-12 | B17: 12/27/2023 | C17: Div. Adj(NRA Withheld) | D17: MCHI | E17: DIV tax withholding on $1.08 at 15% for tax country THA; w8w9: w8 | F17: -0.16
A18: 2023-12 | B18: 12/28/2023 | C18: Journal Entry(Cash) | E18: ID: 09c37510-9bc2-44e1-9d1b-62867750d5fb - STKSWI20231228053645057992 | F18: 29.17
A19: 2024-01 | B19: 01/08/2024 | C19: Div. Adj(NRA Withheld) | D19: VNAM | E19: DIV tax withholding on $0.1 at 15% for tax country THA; w8w9: w8 | F19: -0.01
A20: 2024-01 | B20: 01/08/2024 | C20: Dividends | D20: VNAM | E20: Cash DIV @ 0.05168, Pos QTY: 2, Rec Date: 2023-12-29 | F20: 0.1
A21: 2024-01 | B21: 01/08/2024 | C21: Journal Entry(Cash) | E21: ID: e65045d0-447e-4064-83ea-b959ff3c1835 - STKSWI20240108032719103957 | F21: 40
A22: 2024-02 | B22: 02/01/2024 | C22: Journal Entry(Cash) | E22: ID: c0ea41b8-87c9-47da-b9dd-43ae9c62ec85 - STKSWI20240201051107229712 | F22: 141.2
A23: 2024-03 | B23: 03/07/2024 | C23: Dividends | D23: SHV | E23: Cash DIV @ 0.447689, Pos QTY: 1.28167889, Rec Date: 2024-03-04 | F23: 0.57
A24: 2024-03 | B24: 03/07/2024 | C24: Div. Adj(NRA Withheld) | D24: SHV | E24: DIV tax withholding on $0.57 at 15% for tax country THA; w8w9: w8 | F24: -0.08
A25: 2024-03 | B25: 03/07/2024 | C25: Journal Entry(Cash) | E25: ID: c9955775-a483-4de7-aa8d-4f924fec428e - STKSWI20240307055921511775 | F25: 56.1
A26: 2024-03 | B26: 03/08/2024 | C26: Journal Entry(Cash) | E26: ID: b77cd62d-a305-4db7-9248-764b343b42c7 - STKSWI20240308031250520265 | F26: 140.84
A27: 2024-03 | B27: 03/12/2024 | C27: Journal Entry(Cash) | E27: ID: dc34fd94-bff4-43ba-b75d-c6a002a9d1aa - STKSWI20240312052311551772 | F27: 69.73
A28: 2024-03 | B28: 03/12/2024 | C28: Journal Entry(Cash) | E28: ID: 6588f7bc-a372-44a1-bb15-46ef94aa70ca - STKSWI20240312054413551968 | F28: 41.85
A29: 2024-03 | B29: 03/26/2024 | C29: Dividends | D29: QYLD | E29: Cash DIV @ 0.178, Pos QTY: 2.324061196, Rec Date: 2024-03-19 | F29: 0.41
A30: 2024-03 | B30: 03/26/2024 | C30: Div. Adj(NRA Withheld) | D30: QYLD | E30: DIV tax withholding on $0.41 at 15% for tax country THA; w8w9: w8 | F30: -0.06
A31: 2024-03 | B31: 03/28/2024 | C31: Div. Adj(NRA Withheld) | D31: NDAQ | E31: DIV tax withholding on $0.23 at 15% for tax country THA; w8w9: w8 | F31: -0.03
A32: 2024-03 | B32: 03/28/2024 | C32: Dividends | D32: NDAQ | E32: Cash DIV @ 0.22, Pos QTY: 1.031163562, Rec Date: 2024-03-14 | F32: 0.23
A33: 2024-04 | B33: 04/01/2024 | C33: Journal Entry(Cash) | E33: ID: 435c3202-2f87-4370-9069-f79ef62e8401 - STKSWI20240401022927733357 | F33: 1909.95
A34: 2024-04 | B34: 04/01/2024 | C34: Journal Entry(Cash) | E34: ID: 82b7046f-7243-495d-882e-31d1ec6a2aa2 - STKSWI20240401025816735120 | F34: 272.92
A35: 2024-04 | B35: 04/01/2024 | C35: Journal Entry(Cash) | E35: ID: 4432c579-1035-48e6-b68f-0c71585c936f - STKSWI20240401030332735375 | F35: 545.55
A36: 2024-04 | B36: 04/05/2024 | C36: Div. Adj(NRA Withheld) | D36: SGOV | E36: DIV tax withholding on $0.31 at 15% for tax country THA; w8w9: w8 | F36: -0.04
A37: 2024-04 | B37: 04/05/2024 | C37: Div. Adj(NRA Withheld) | D37: SHV | E37: DIV tax withholding on $1.48 at 15% for tax country THA; w8w9: w8 | F37: -0.22
A38: 2024-04 | B38: 04/05/2024 | C38: Dividends | D38: SHV | E38: Cash DIV @ 0.481925, Pos QTY: 3.066391235, Rec Date: 2024-04-02 | F38: 1.48
A39: 2024-04 | B39: 04/05/2024 | C39: Dividends | D39: SGOV | E39: Cash DIV @ 0.449911, Pos QTY: 0.693025941, Rec Date: 2024-04-02 | F39: 0.31
A40: 2024-04 | B40: 04/18/2024 | C40: Journal Entry(Cash) | E40: ID: b3395d97-4841-4216-9eed-9234484b20f6 - STKSWI20240418061446904605 | F40: 135.5
...

Sheet Fees
A1: Month | B1: Trade Date | C1: Description | D1: Net Amt
A2: 2025-02 | B2: 02/10/2025 | C2: REG fee for proceed of $445.55 on 2025-02-10 by 947159514 | D2: -0.02
A3: 2025-02 | B3: 02/10/2025 | C3: TAF fee for proceed of 9.02418951 shares (2 trades) on 2025-02-10 by 947159514 | D3: -0.01
A4: 2025-04 | B4: 04/07/2025 | C4: REG fee for proceed of $84.66 on 2025-04-07 by 947159514 | D4: -0.01
A5: 2025-04 | B5: 04/07/2025 | C5: TAF fee for proceed of 1.802738992 shares (2 trades) on 2025-04-07 by 947159514 | D5: -0.01
A6: 2025-04 | B6: 04/21/2025 | C6: REG fee for proceed of $878.6 on 2025-04-21 by 947159514 | D6: -0.03
A7: 2025-04 | B7: 04/21/2025 | C7: TAF fee for proceed of 58.138237982 shares (2 trades) on 2025-04-21 by 947159514 | D7: -0.01
A8: 2025-05 | B8: 05/16/2025 | C8: TAF fee for proceed of 55 shares (1 trades) on 2025-05-16 by 947159514 | D8: -0.01
A9: 2025-06 | B9: 06/10/2025 | C9: CAT fee for proceed of 1 trades on 2025-06-10 by 947159514 | D9: -0.01
A10: 2025-06 | B10: 06/11/2025 | C10: CAT fee for proceed of 1 trades on 2025-06-11 by 947159514 | D10: -0.01
A11: 2025-06 | B11: 06/12/2025 | C11: CAT fee for proceed of 1 trades on 2025-06-12 by 947159514 | D11: -0.01
A12: 2025-06 | B12: 06/13/2025 | C12: CAT fee for proceed of 9 trades on 2025-06-13 by 947159514 | D12: -0.01
A13: 2025-06 | B13: 06/13/2025 | C13: TAF fee for proceed of 31 shares (2 trades) on 2025-06-13 by 947159514 | D13: -0.01
... A75: 2026-04 | B75: 04/28/2026 | C75: TAF fee for proceed of 13.649461997 shares (2 trades) on 2026-04-28 by 947159514 | D75: -0.01

Sheet Deposits & Withdrawals
A1: Month | B1: Trade Date | C1: Entry Type | D1: Description | E1: Net Amt | F1: Account No
A2: 2024-11 | B2: 11/01/2024 | C2: Journal Entry(Cash) | D2: STKSWI20241101032526417426 | E2: 881.05 | F2: 947159514
A3: 2024-11 | B3: 11/01/2024 | C3: Journal Entry(Cash) | D3: STKSWI20241101033632417975 | E3: 587.37 | F3: 947159514
A4: 2024-11 | B4: 11/25/2024 | C4: Journal Entry(Cash) | D4: STKSWI20241125042536876644 | E4: 287.52 | F4: 947159514
A5: 2024-11 | B5: 11/27/2024 | C5: Journal Entry(Cash) | D5: STKSWI20241127044827937623 | E5: 1445.92 | F5: 947159514
A6: 2024-12 | B6: 12/20/2024 | C6: Journal Entry(Cash) | D6: STKSWI20241220034703511182 | E6: 193.76 | F6: 947159514
A7: 2024-12 | B7: 12/20/2024 | C7: Journal Entry(Cash) | D7: STKSWI20241220035008511413 | E7: 184 | F7: 947159514
A8: 2024-12 | B8: 12/23/2024 | C8: Journal Entry(Cash) | D8: STKSWI20241223033928553487 | E8: 184 | F8: 947159514
A9: 2024-12 | B9: 12/23/2024 | C9: Journal Entry(Cash) | D9: STKSWI20241223034107553610 | E9: 184 | F9: 947159514
A10: 2024-12 | B10: 12/31/2024 | C10: Journal Entry(Cash) | D10: STKSWI20241231053543777802 | E10: 183 | F10: 947159514
A11: 2024-12 | B11: 12/31/2024 | C11: Journal Entry(Cash) | D11: STKSWI20241231044607776220 | E11: 367 | F11: 947159514
A12: 2024-12 | B12: 12/31/2024 | C12: Journal Entry(Cash) | D12: STKSWI20241231052307777157 | E12: 183 | F12: 947159514
A13: 2024-12 | B13: 12/31/2024 | C13: Journal Entry(Cash) | D13: STKSWI20241231052614777300 | E13: 173.64 | F13: 947159514
... A202: 2026-04 | B202: 04/13/2026 | C202: Journal Entry(Cash) | D202: STKSWI20260413021419162696 | E202: 156 | F202: 947159514

Sheet Validation
A1: Month | B1: Cash Identity Diff ($) | C1: Txn Sum vs Trade Transaction ($) | D1: Gross Dividends Sum vs Summary ($) | E1: Holdings Sum vs Long ($) | F1: Prior Ending vs Beginning ($) | G1: Note
A2: 2023-01 | B2: =ROUND(Summary!D2+Summary!E2-Summary!F2+Summary!G2+Summary!H2-Summary!I2,2) -> 0 | C2: =ROUND(SUMIFS(Transactions!I:I,Transactions!A:A,A2)-Summary!G2,2) -> 0 | D2: =ROUND(SUMIFS(Income!F:F,Income!A:A,A2,Income!C:C,"Dividends")-Summary!L2,2) -> 0 | E2: =ROUND(SUMIFS(Holdings!F:F,Holdings!A:A,A2,Holdings!B:B,"<>*Cash")-Summary!J2,2) -> 0 | G2: Holdings diff of few cents = statement's own per-row rounding (verified against PDF text)
A3: 2023-02 | B3: =ROUND(Summary!D3+Summary!E3-Summary!F3+Summary!G3+Summary!H3-Summary!I3,2) -> 0 | C3: =ROUND(SUMIFS(Transactions!I:I,Transactions!A:A,A3)-Summary!G3,2) -> 0 | D3: =ROUND(SUMIFS(Income!F:F,Income!A:A,A3,Income!C:C,"Dividends")-Summary!L3,2) -> 0 | E3: =ROUND(SUMIFS(Holdings!F:F,Holdings!A:A,A3,Holdings!B:B,"<>*Cash")-Summary!J3,2) -> 0 | F3: =ROUND(Summary!I2-Summary!D3,2) -> 0 | G3: Holdings diff of few cents = statement's own per-row rounding (verified against PDF text)
A4: 2023-03 | B4: =ROUND(Summary!D4+Summary!E4-Summary!F4+Summary!G4+Summary!H4-Summary!I4,2) -> 0 | C4: =ROUND(SUMIFS(Transactions!I:I,Transactions!A:A,A4)-Summary!G4,2) -> 0 | D4: =ROUND(SUMIFS(Income!F:F,Income!A:A,A4,Income!C:C,"Dividends")-Summary!L4,2) -> 0 | E4: =ROUND(SUMIFS(Holdings!F:F,Holdings!A:A,A4,Holdings!B:B,"<>*Cash")-Summary!J4,2) -> 0 | F4: =ROUND(Summary!I3-Summary!D4,2) -> 0 | G4: Holdings diff of few cents = statement's own per-row rounding (verified against PDF text)
A5: 2023-04 | B5: =ROUND(Summary!D5+Summary!E5-Summary!F5+Summary!G5+Summary!H5-Summary!I5,2) -> 0 | C5: =ROUND(SUMIFS(Transactions!I:I,Transactions!A:A,A5)-Summary!G5,2) -> 0 | D5: =ROUND(SUMIFS(Income!F:F,Income!A:A,A5,Income!C:C,"Dividends")-Summary!L5,2) -> 0 | E5: =ROUND(SUMIFS(Holdings!F:F,Holdings!A:A,A5,Holdings!B:B,"<>*Cash")-Summary!J5,2) -> 0 | F5: =ROUND(Summary!I4-Summary!D5,2) -> 0 | G5: Holdings diff of few cents = statement's own per-row rounding (verified against PDF text)
A6: 2023-05 | B6: =ROUND(Summary!D6+Summary!E6-Summary!F6+Summary!G6+Summary!H6-Summary!I6,2) -> 0 | C6: =ROUND(SUMIFS(Transactions!I:I,Transactions!A:A,A6)-Summary!G6,2) -> 0 | D6: =ROUND(SUMIFS(Income!F:F,Income!A:A,A6,Income!C:C,"Dividends")-Summary!L6,2) -> 0 | E6: =ROUND(SUMIFS(Holdings!F:F,Holdings!A:A,A6,Holdings!B:B,"<>*Cash")-Summary!J6,2) -> 0 | F6: =ROUND(Summary!I5-Summary!D6,2) -> 0 | G6: Holdings diff of few cents = statement's own per-row rounding (verified against PDF text)
A7: 2023-06 | B7: =ROUND(Summary!D7+Summary!E7-Summary!F7+Summary!G7+Summary!H7-Summary!I7,2) -> 0 | C7: =ROUND(SUMIFS(Transactions!I:I,Transactions!A:A,A7)-Summary!G7,2) -> 0 | D7: =ROUND(SUMIFS(Income!F:F,Income!A:A,A7,Income!C:C,"Dividends")-Summary!L7,2) -> 0 | E7: =ROUND(SUMIFS(Holdings!F:F,Holdings!A:A,A7,Holdings!B:B,"<>*Cash")-Summary!J7,2) -> 0 | F7: =ROUND(Summary!I6-Summary!D7,2) -> 0 | G7: Holdings diff of few cents = statement's own per-row rounding (verified against PDF text)
A8: 2023-07 | B8: =ROUND(Summary!D8+Summary!E8-Summary!F8+Summary!G8+Summary!H8-Summary!I8,2) -> 0 | C8: =ROUND(SUMIFS(Transactions!I:I,Transactions!A:A,A8)-Summary!G8,2) -> 0 | D8: =ROUND(SUMIFS(Income!F:F,Income!A:A,A8,Income!C:C,"Dividends")-Summary!L8,2) -> 0 | E8: =ROUND(SUMIFS(Holdings!F:F,Holdings!A:A,A8,Holdings!B:B,"<>*Cash")-Summary!J8,2) -> -0.01 | F8: =ROUND(Summary!I7-Summary!D8,2) -> 0 | G8: Holdings diff of few cents = statement's own per-row rounding (verified against PDF text)
A9: 2023-08 | B9: =ROUND(Summary!D9+Summary!E9-Summary!F9+Summary!G9+Summary!H9-Summary!I9,2) -> 0 | C9: =ROUND(SUMIFS(Transactions!I:I,Transactions!A:A,A9)-Summary!G9,2) -> 0 | D9: =ROUND(SUMIFS(Income!F:F,Income!A:A,A9,Income!C:C,"Dividends")-Summary!L9,2) -> 0 | E9: =ROUND(SUMIFS(Holdings!F:F,Holdings!A:A,A9,Holdings!B:B,"<>*Cash")-Summary!J9,2) -> 0.01 | F9: =ROUND(Summary!I8-Summary!D9,2) -> 0 | G9: Holdings diff of few cents = statement's own per-row rounding (verified against PDF text)
A10: 2023-09 | B10: =ROUND(Summary!D10+Summary!E10-Summary!F10+Summary!G10+Summary!H10-Summary!I10,2) -> 0 | C10: =ROUND(SUMIFS(Transactions!I:I,Transactions!A:A,A10)-Summary!G10,2) -> 0 | D10: =ROUND(SUMIFS(Income!F:F,Income!A:A,A10,Income!C:C,"Dividends")-Summary!L10,2) -> 0 | E10: =ROUND(SUMIFS(Holdings!F:F,Holdings!A:A,A10,Holdings!B:B,"<>*Cash")-Summary!J10,2) -> 0 | F10: =ROUND(Summary!I9-Summary!D10,2) -> 0 | G10: Holdings diff of few cents = statement's own per-row rounding (verified against PDF text)
A11: 2023-10 | B11: =ROUND(Summary!D11+Summary!E11-Summary!F11+Summary!G11+Summary!H11-Summary!I11,2) -> 0 | C11: =ROUND(SUMIFS(Transactions!I:I,Transactions!A:A,A11)-Summary!G11,2) -> 0 | D11: =ROUND(SUMIFS(Income!F:F,Income!A:A,A11,Income!C:C,"Dividends")-Summary!L11,2) -> 0 | E11: =ROUND(SUMIFS(Holdings!F:F,Holdings!A:A,A11,Holdings!B:B,"<>*Cash")-Summary!J11,2) -> 0.01 | F11: =ROUND(Summary!I10-Summary!D11,2) -> 0 | G11: Holdings diff of few cents = statement's own per-row rounding (verified against PDF text)
A12: 2023-11 | B12: =ROUND(Summary!D12+Summary!E12-Summary!F12+Summary!G12+Summary!H12-Summary!I12,2) -> 0 | C12: =ROUND(SUMIFS(Transactions!I:I,Transactions!A:A,A12)-Summary!G12,2) -> 0 | D12: =ROUND(SUMIFS(Income!F:F,Income!A:A,A12,Income!C:C,"Dividends")-Summary!L12,2) -> 0 | E12: =ROUND(SUMIFS(Holdings!F:F,Holdings!A:A,A12,Holdings!B:B,"<>*Cash")-Summary!J12,2) -> 0 | F12: =ROUND(Summary!I11-Summary!D12,2) -> 0 | G12: Holdings diff of few cents = statement's own per-row rounding (verified against PDF text)
A13: 2023-12 | B13: =ROUND(Summary!D13+Summary!E13-Summary!F13+Summary!G13+Summary!H13-Summary!I13,2) -> 0 | C13: =ROUND(SUMIFS(Transactions!I:I,Transactions!A:A,A13)-Summary!G13,2) -> 0 | D13: =ROUND(SUMIFS(Income!F:F,Income!A:A,A13,Income!C:C,"Dividends")-Summary!L13,2) -> 0 | E13: =ROUND(SUMIFS(Holdings!F:F,Holdings!A:A,A13,Holdings!B:B,"<>*Cash")-Summary!J13,2) -> 0 | F13: =ROUND(Summary!I12-Summary!D13,2) -> 0 | G13: Holdings diff of few cents = statement's own per-row rounding (verified against PDF text)
A14: 2024-01 | B14: =ROUND(Summary!D14+Summary!E14-Summary!F14+Summary!G14+Summary!H14-Summary!I14,2) -> 0 | C14: =ROUND(SUMIFS(Transactions!I:I,Transactions!A:A,A14)-Summary!G14,2) -> 0 | D14: =ROUND(SUMIFS(Income!F:F,Income!A:A,A14,Income!C:C,"Dividends")-Summary!L14,2) -> 0 | E14: =ROUND(SUMIFS(Holdings!F:F,Holdings!A:A,A14,Holdings!B:B,"<>*Cash")-Summary!J14,2) -> 0 | F14: =ROUND(Summary!I13-Summary!D14,2) -> 0 | G14: Holdings diff of few cents = statement's own per-row rounding (verified against PDF text)
... A41: 2026-04 | B41: =ROUND(Summary!D41+Summary!E41-Summary!F41+Summary!G41+Summary!H41-Summary!I41,2) -> 0 | C41: =ROUND(SUMIFS(Transactions!I:I,Transactions!A:A,A41)-Summary!G41,2) -> 0 | D41: =ROUND(SUMIFS(Income!F:F,Income!A:A,A41,Income!C:C,"Dividends")-Summary!L41,2) -> 0 | E41: =ROUND(SUMIFS(Holdings!F:F,Holdings!A:A,A41,Holdings!B:B,"<>*Cash")-Summary!J41,2) -> 0.02 | F41: =ROUND(Summary!I40-Summary!D41,2) -> 0 | G41: Holdings diff of few cents = statement's own per-row rounding (verified against PDF text)
